Workbook

Sheet Feuille 1
A1: To | B1: From | C1: Type | D1: t'as amené | E1: Remarque | F1: Colour
A2: Lucile Ca | B2: Jules Ca | C2: fratrie
A3: Lucile Ca | B3: Emile Ca | C3: fratrie
A4: Lucile Ca | B4: Gaelle Ca | C4: fratrie
A5: Jules Ca | B5: Emile Ca | C5: fratrie
A6: Jules Ca | B6: Gaelle Ca | C6: fratrie
A7: Emile Ca | B7: Gaelle Ca | C7: fratrie
A8: Nina Le | B8: Gaelle Ca | C8: ami.es
A9: Nina Le | B9: Jules Ca
A10: Nina Le | B10: Lucile Ca | C10: ami.es
A11: Nina Le | B11: Emile Ca | C11: ami.es
A12: Nina Le | B12: Malorie Ro | C12: ami.es
A13: Margaux Co | B13: Jules Ca | C13: cousin.es
A14: Margaux Co | B14: Gaelle Ca | C14: cousin.es
A15: Margaux Co | B15: Lucile Ca | C15: cousin.es
A16: Margaux Co | B16: Emile Ca | C16: cousin.es
A17: Margaux Co | B17: Etienna La | C17: relation
A18: Lucile Ca | B18: Lizza Ve | C18: relation
A19: Lizza Ve | B19: Lisa Lo | C19: ami.es
A20: Lizza Ve | B20: Manon Mo | C20: ami.es
A21: Lizza Ve | B21: Mathis BR | C21: ami.es
A22: Lizza Ve | B22: Louise Al | C22: ami.es | E22: coloc
A23: Lizza Ve | B23: Adam In | C23: ami.es
A24: Lucile Ca | B24: Lisa Lo | C24: ami.es
A25: Lisa Lo | B25: Manon Mo | C25: ami.es
A26: Lisa Lo | B26: Mathis BR | C26: ami.es
A27: Lisa Lo | B27: Adam In | C27: ami.es
A28: Lucile Ca | B28: Edeina MJ | C28: ami.es
A29: Lucile Ca | B29: Manon Mo | C29: ami.es
A30: Manon Mo | B30: Mathis BR | C30: ami.es
A31: Manon Mo | B31: Adam In | C31: ami.es
A32: Lucile Ca | B32: Mathis BR | C32: ami.es
A33: Mathis BR | B33: Serena | C33: relation
A34: Mathis BR | B34: Adam In | C34: ami.es
... A36: Lucile Ca | B36: Adam In | C36: ami.es
A37: Gaelle Ca | B37: Malorie Ro | C37: ami.es | E37: cadiergue adoptée
A38: Malorie Ro | B38: Lucile Ca | C38: ami.es | E38: cadiergue adoptée
A39: Gaelle Ca | B39: Maelys Du | C39: ami.es
A40: Gaelle Ca | B40: Téo Pe | C40: ami.es | E40: mouais
A41: Gaelle Ca | B41: Manon Br | C41: ami.es
...

Sheet Proposition rentrée
A1: Team | C1: Jules Ca | D1: Emile Ca | E1: Gaëlle Ca | F1: Lucile Ca | G1: Margaux Co | H1: Etienne La | I1: Nina Le | J1: Anne-Flore Du | K1: Rémi Pe | L1: Diego Gu | M1: Angélique Wa | N1: Louise Pr | O1: Victor Di | P1: Hugo Pa | Q1: Sydney Co | R1: Valentin Ma | S1: Léonard Gu | T1: Lizza Ve | U1: Lisa Lo | V1: Edeina MJ | W1: Manon Mo | X1: Mathis BR | Y1: Louise Al | Z1: Adam In | AA1: Serena Po | AB1: Malorie Ro | AC1: Maelys Du | AD1: Téo Pe | AE1: Flora Ta | AF1: Manon Br | AG1: Emi Jo | AH1: Arthur Ba | AI1: Alexis Le | AJ1: Kévin | AK1: Julia Fo | AL1: Johan Ro | AM1: Clémence Go | AN1: Léa Ch | AO1: Camille Pr | AP1: Hugo Ma | AQ1: Enora Sa | AR1: Margot Th | AS1: Elliott De | AT1: Gaëlle MD | AU1: Pierre Fo | AV1: Thaïs PD | AW1: Lucien Popov Le
A2: Mif | B2: Jules Ca
B3: Emile Ca | C3: fratrie
B4: Gaëlle Ca | C4: fratrie | D4: fratrie
B5: Lucile Ca | C5: fratrie | D5: fratrie | E5: fratrie
B6: Margaux Co | C6: cousin.es | D6: cousin.es | E6: cousin.es | F6: cousin.es
B7: Etienne La | G7: relation
B8: Nina Le
A9: Jules | B9: Anne-Flore Du | C9: relation
B10: Rémi Pe
B11: Diego Gu
B12: Angélique Wa
B13: Louise Pr
B14: Victor Di
B15: Hugo Pa
B16: Sydney Co
B17: Valentin Ma
B18: Léonard Gu
A19: Lucile | B19: Lizza Ve
B20: Lisa Lo
B21: Edeina MJ
B22: Manon Mo
B23: Mathis BR
B24: Louise Al
B25: Adam In
B26: Serena Po
A27: Gaëlle | B27: Malorie Ro
B28: Maelys Du
B29: Téo Pe
B30: Flora Ta
B31: Manon Br
B32: Emi Jo
A33: Émile | B33: Arthur Ba
B34: Alexis Le
B35: Kévin
B36: Julia Fo
B37: Johan Ro
B38: Clémence Go
B39: Léa Ch
B40: Camille Pr
...

Sheet 2.0
A1: To | B1: From
A2: Jules Ca | B2: Emile Ca | C2: ='Proposition rentrée'!C3 -> fratrie
A3: Jules Ca | B3: Gaëlle Ca | C3: ='Proposition rentrée'!C4 -> fratrie
A4: Jules Ca | B4: Lucile Ca | C4: ='Proposition rentrée'!C5 -> fratrie
A5: Jules Ca | B5: Margaux Co | C5: ='Proposition rentrée'!C6 -> cousin.es
A6: Jules Ca | B6: Etienne La | C6: ='Proposition rentrée'!C7 -> 0
A7: Jules Ca | B7: Nina Le | C7: ='Proposition rentrée'!C8 -> 0
A8: Jules Ca | B8: Anne-Flore Du | C8: ='Proposition rentrée'!C9 -> relation
A9: Jules Ca | B9: Rémi Pe | C9: ='Proposition rentrée'!C10 -> 0
A10: Jules Ca | B10: Diego Gu | C10: ='Proposition rentrée'!C11 -> 0
A11: Jules Ca | B11: Angélique Wa | C11: ='Proposition rentrée'!C12 -> 0
A12: Jules Ca | B12: Louise Pr | C12: ='Proposition rentrée'!C13 -> 0
A13: Jules Ca | B13: Victor Di | C13: ='Proposition rentrée'!C14 -> 0
... A47: Jules Ca | B47: Lucien Popov Le | C47: ='Proposition rentrée'!C48 -> 0
A48: Emile Ca | B48: Gaëlle Ca | C48: ='Proposition rentrée'!D4 -> fratrie
A49: Emile Ca | B49: Lucile Ca | C49: ='Proposition rentrée'!D5 -> fratrie
A50: Emile Ca | B50: Margaux Co | C50: ='Proposition rentrée'!D6 -> cousin.es
A51: Emile Ca | B51: Etienne La | C51: ='Proposition rentrée'!D7 -> 0
A52: Emile Ca | B52: Nina Le | C52: ='Proposition rentrée'!D8 -> 0
A53: Emile Ca | B53: Anne-Flore Du | C53: ='Proposition rentrée'!D9 -> 0
A54: Emile Ca | B54: Rémi Pe | C54: ='Proposition rentrée'!D10 -> 0
A55: Emile Ca | B55: Diego Gu | C55: ='Proposition rentrée'!D11 -> 0
A56: Emile Ca | B56: Angélique Wa | C56: ='Proposition rentrée'!D12 -> 0
A57: Emile Ca | B57: Louise Pr | C57: ='Proposition rentrée'!D13 -> 0
A58: Emile Ca | B58: Victor Di | C58: ='Proposition rentrée'!D14 -> 0
A59: Emile Ca | B59: Hugo Pa | C59: ='Proposition rentrée'!D15 -> 0
... A92: Emile Ca | B92: Lucien Popov Le | C92: ='Proposition rentrée'!D48 -> 0
A93: Gaëlle Ca | B93: Lucile Ca | C93: ='Proposition rentrée'!E5 -> fratrie
A94: Gaëlle Ca | B94: Margaux Co | C94: ='Proposition rentrée'!E6 -> cousin.es
A95: Gaëlle Ca | B95: Etienne La | C95: ='Proposition rentrée'!E7 -> 0
A96: Gaëlle Ca | B96: Nina Le | C96: ='Proposition rentrée'!E8 -> 0
A97: Gaëlle Ca | B97: Anne-Flore Du | C97: ='Proposition rentrée'!E9 -> 0
A98: Gaëlle Ca | B98: Rémi Pe | C98: ='Proposition rentrée'!E10 -> 0
A99: Gaëlle Ca | B99: Diego Gu | C99: ='Proposition rentrée'!E11 -> 0
A100: Gaëlle Ca | B100: Angélique Wa | C100: ='Proposition rentrée'!E12 -> 0
A101: Gaëlle Ca | B101: Louise Pr | C101: ='Proposition rentrée'!E13 -> 0
A102: Gaëlle Ca | B102: Victor Di | C102: ='Proposition rentrée'!E14 -> 0
A103: Gaëlle Ca | B103: Hugo Pa | C103: ='Proposition rentrée'!E15 -> 0
A104: Gaëlle Ca | B104: Sydney Co | C104: ='Proposition rentrée'!E16 -> 0
... A136: Gaëlle Ca | B136: Lucien Popov Le | C136: ='Proposition rentrée'!E48 -> 0
...

Sheet Copie de 2.0
A1: To | B1: From
A2: Jules Ca | B2: Jules Ca | C2: ='Proposition rentrée'!C2 -> 0
A3: Jules Ca | B3: Emile Ca | C3: ='Proposition rentrée'!C3 -> fratrie
A4: Jules Ca | B4: Gaëlle Ca | C4: ='Proposition rentrée'!C4 -> fratrie
A5: Jules Ca | B5: Lucile Ca | C5: ='Proposition rentrée'!C5 -> fratrie
A6: Jules Ca | B6: Margaux Co | C6: ='Proposition rentrée'!C6 -> cousin.es
A7: Jules Ca | B7: Etienne La | C7: ='Proposition rentrée'!C7 -> 0
A8: Jules Ca | B8: Nina Le | C8: ='Proposition rentrée'!C8 -> 0
A9: Jules Ca | B9: Anne-Flore Du | C9: ='Proposition rentrée'!C9 -> relation
A10: Jules Ca | B10: Rémi Pe | C10: ='Proposition rentrée'!C10 -> 0
A11: Jules Ca | B11: Diego Gu | C11: ='Proposition rentrée'!C11 -> 0
A12: Jules Ca | B12: Angélique Wa | C12: ='Proposition rentrée'!C12 -> 0
A13: Jules Ca | B13: Louise Pr | C13: ='Proposition rentrée'!C13 -> 0
... A48: Jules Ca | B48: Lucien Popov Le | C48: ='Proposition rentrée'!C48 -> 0
B49: Jules Ca | C49: ='Proposition rentrée'!D2 -> 0
A50: Emile Ca | B50: Emile Ca | C50: ='Proposition rentrée'!D3 -> 0
A51: Emile Ca | B51: Gaëlle Ca | C51: ='Proposition rentrée'!D4 -> fratrie
A52: Emile Ca | B52: Lucile Ca | C52: ='Proposition rentrée'!D5 -> fratrie
A53: Emile Ca | B53: Margaux Co | C53: ='Proposition rentrée'!D6 -> cousin.es
A54: Emile Ca | B54: Etienne La | C54: ='Proposition rentrée'!D7 -> 0
A55: Emile Ca | B55: Nina Le | C55: ='Proposition rentrée'!D8 -> 0
A56: Emile Ca | B56: Anne-Flore Du | C56: ='Proposition rentrée'!D9 -> 0
A57: Emile Ca | B57: Rémi Pe | C57: ='Proposition rentrée'!D10 -> 0
A58: Emile Ca | B58: Diego Gu | C58: ='Proposition rentrée'!D11 -> 0
A59: Emile Ca | B59: Angélique Wa | C59: ='Proposition rentrée'!D12 -> 0
A60: Emile Ca | B60: Louise Pr | C60: ='Proposition rentrée'!D13 -> 0
A61: Emile Ca | B61: Victor Di | C61: ='Proposition rentrée'!D14 -> 0
... A95: Emile Ca | B95: Lucien Popov Le | C95: ='Proposition rentrée'!D48 -> 0
B96: Jules Ca | C96: ='Proposition rentrée'!E2 -> 0
B97: Emile Ca | C97: ='Proposition rentrée'!E3 -> 0
A98: Gaëlle Ca | B98: Gaëlle Ca | C98: ='Proposition rentrée'!E4 -> 0
A99: Gaëlle Ca | B99: Lucile Ca | C99: ='Proposition rentrée'!E5 -> fratrie
A100: Gaëlle Ca | B100: Margaux Co | C100: ='Proposition rentrée'!E6 -> cousin.es
A101: Gaëlle Ca | B101: Etienne La | C101: ='Proposition rentrée'!E7 -> 0
A102: Gaëlle Ca | B102: Nina Le | C102: ='Proposition rentrée'!E8 -> 0
A103: Gaëlle Ca | B103: Anne-Flore Du | C103: ='Proposition rentrée'!E9 -> 0
A104: Gaëlle Ca | B104: Rémi Pe | C104: ='Proposition rentrée'!E10 -> 0
A105: Gaëlle Ca | B105: Diego Gu | C105: ='Proposition rentrée'!E11 -> 0
A106: Gaëlle Ca | B106: Angélique Wa | C106: ='Proposition rentrée'!E12 -> 0
A107: Gaëlle Ca | B107: Louise Pr | C107: ='Proposition rentrée'!E13 -> 0
...
